2019-01-17 17:21:12,134 ERROR: Unhandled exception [in ./app/tasks.py:36]
Traceback (most recent call last):
  File "/Users/tw4204/git/flask/venv/lib/python3.7/site-packages/flask_mail.py", line 492, in send
    message.send(connection)
  File "/Users/tw4204/git/flask/venv/lib/python3.7/site-packages/flask_mail.py", line 427, in send
    connection.send(self)
  File "/Users/tw4204/git/flask/venv/lib/python3.7/site-packages/flask_mail.py", line 192, in send
    message.rcpt_options)
  File "/usr/local/Cellar/python/3.7.2/Frameworks/Python.framework/Versions/3.7/lib/python3.7/smtplib.py", line 852, in sendmail
    self.ehlo_or_helo_if_needed()
  File "/usr/local/Cellar/python/3.7.2/Frameworks/Python.framework/Versions/3.7/lib/python3.7/smtplib.py", line 600, in ehlo_or_helo_if_needed
    if not (200 <= self.ehlo()[0] <= 299):
  File "/usr/local/Cellar/python/3.7.2/Frameworks/Python.framework/Versions/3.7/lib/python3.7/smtplib.py", line 440, in ehlo
    self.putcmd(self.ehlo_msg, name or self.local_hostname)
  File "/usr/local/Cellar/python/3.7.2/Frameworks/Python.framework/Versions/3.7/lib/python3.7/smtplib.py", line 367, in putcmd
    self.send(str)
  File "/usr/local/Cellar/python/3.7.2/Frameworks/Python.framework/Versions/3.7/lib/python3.7/smtplib.py", line 359, in send
    raise SMTPServerDisconnected('please run connect() first')
smtplib.SMTPServerDisconnected: please run connect() first

During handling of the above exception, another exception occurred:

Traceback (most recent call last):
  File "./app/tasks.py", line 32, in export_posts
    sync=True)
  File "./app/email.py", line 18, in send_email
    mail.send(msg)
  File "/Users/tw4204/git/flask/venv/lib/python3.7/site-packages/flask_mail.py", line 492, in send
    message.send(connection)
  File "/Users/tw4204/git/flask/venv/lib/python3.7/site-packages/flask_mail.py", line 152, in __exit__
    self.host.quit()
  File "/usr/local/Cellar/python/3.7.2/Frameworks/Python.framework/Versions/3.7/lib/python3.7/smtplib.py", line 984, in quit
    res = self.docmd("quit")
  File "/usr/local/Cellar/python/3.7.2/Frameworks/Python.framework/Versions/3.7/lib/python3.7/smtplib.py", line 420, in docmd
    self.putcmd(cmd, args)
  File "/usr/local/Cellar/python/3.7.2/Frameworks/Python.framework/Versions/3.7/lib/python3.7/smtplib.py", line 367, in putcmd
    self.send(str)
  File "/usr/local/Cellar/python/3.7.2/Frameworks/Python.framework/Versions/3.7/lib/python3.7/smtplib.py", line 359, in send
    raise SMTPServerDisconnected('please run connect() first')
smtplib.SMTPServerDisconnected: please run connect() first
2019-01-17 17:28:16,141 INFO: Microblog startup [in ./app/__init__.py:70]
2019-01-17 17:28:16,267 ERROR: Unhandled exception [in ./app/tasks.py:36]
Traceback (most recent call last):
  File "/Users/tw4204/git/flask/venv/lib/python3.7/site-packages/flask_mail.py", line 492, in send
    message.send(connection)
  File "/Users/tw4204/git/flask/venv/lib/python3.7/site-packages/flask_mail.py", line 427, in send
    connection.send(self)
  File "/Users/tw4204/git/flask/venv/lib/python3.7/site-packages/flask_mail.py", line 192, in send
    message.rcpt_options)
  File "/usr/local/Cellar/python/3.7.2/Frameworks/Python.framework/Versions/3.7/lib/python3.7/smtplib.py", line 852, in sendmail
    self.ehlo_or_helo_if_needed()
  File "/usr/local/Cellar/python/3.7.2/Frameworks/Python.framework/Versions/3.7/lib/python3.7/smtplib.py", line 600, in ehlo_or_helo_if_needed
    if not (200 <= self.ehlo()[0] <= 299):
  File "/usr/local/Cellar/python/3.7.2/Frameworks/Python.framework/Versions/3.7/lib/python3.7/smtplib.py", line 440, in ehlo
    self.putcmd(self.ehlo_msg, name or self.local_hostname)
  File "/usr/local/Cellar/python/3.7.2/Frameworks/Python.framework/Versions/3.7/lib/python3.7/smtplib.py", line 367, in putcmd
    self.send(str)
  File "/usr/local/Cellar/python/3.7.2/Frameworks/Python.framework/Versions/3.7/lib/python3.7/smtplib.py", line 359, in send
    raise SMTPServerDisconnected('please run connect() first')
smtplib.SMTPServerDisconnected: please run connect() first

During handling of the above exception, another exception occurred:

Traceback (most recent call last):
  File "./app/tasks.py", line 32, in export_posts
    sync=True)
  File "./app/email.py", line 18, in send_email
    mail.send(msg)
  File "/Users/tw4204/git/flask/venv/lib/python3.7/site-packages/flask_mail.py", line 492, in send
    message.send(connection)
  File "/Users/tw4204/git/flask/venv/lib/python3.7/site-packages/flask_mail.py", line 152, in __exit__
    self.host.quit()
  File "/usr/local/Cellar/python/3.7.2/Frameworks/Python.framework/Versions/3.7/lib/python3.7/smtplib.py", line 984, in quit
    res = self.docmd("quit")
  File "/usr/local/Cellar/python/3.7.2/Frameworks/Python.framework/Versions/3.7/lib/python3.7/smtplib.py", line 420, in docmd
    self.putcmd(cmd, args)
  File "/usr/local/Cellar/python/3.7.2/Frameworks/Python.framework/Versions/3.7/lib/python3.7/smtplib.py", line 367, in putcmd
    self.send(str)
  File "/usr/local/Cellar/python/3.7.2/Frameworks/Python.framework/Versions/3.7/lib/python3.7/smtplib.py", line 359, in send
    raise SMTPServerDisconnected('please run connect() first')
smtplib.SMTPServerDisconnected: please run connect() first
